Workbook

Sheet サマリー
A1: YouTube Factory 指揮者レポート — 2026-09-16
A2: analytics.db 最終同期 2026-09-15 22:41／集計対象は moviepy 6ch の views>0 の動画。数値はすべて他シートを参照する数式で、ハードコードしていない。
A4: 本日の結論
A5: 1. 09-09〜09-12 の 4 日間、公開が 33本/日 から 0〜2本/日 へ全停止していた。09-10〜09-12 はOAuth リフレッシュトークンの一斉失効が原因（失効スキップ 39/24/21 件）。この 3 日間もautopilot は 31/31/28 回発火しており、生成した約 90 本が公開されずに捨てられている。
A6: 2. 13ch 中 7ch がいまも停止中。トークンが生きているのに autopilot=false だったのは 2ch-matome だけだったので、本日 autopilot を戻した（要バックエンド再起動）。
A7: 3. 同意画面が「テスト」のままならトークン寿命は 7 日。09-13 再認可組は 09-20 前後にまた全部止まる。本番公開への切り替えが今日いちばん効く一手で、これは人手でしかできない。
A8: 4. analytics は 09-13 に再開したが 09-09〜09-12 が欠測、加えて views は公開から約 2 日遅れて入る。09-17 に予定していた型ルール・投稿枠の評価は n が足りず実行不能なので 09-23 へ延期した。
A9: 5. 09-15 の「維持率 70%以上は登録効率が最下位」は再現しなかった（0.294 → 0.471）。頂点が 40-50% 帯であることだけが再現。単調な主張は取り下げた。
A10: 6. 最も頑健なのは依然として高評価率。四分位で登録/千再生が単調に増える（Q4/Q1 3.46倍・6回目の再現）。
A12: 主要指標
A13: 指標 | B13: 値 | C13: 参照元 | D13: 読み方
A14: 計測済み動画（6ch・全期間） | B14: =チャンネル別詳細!B11 -> 513 | C14: チャンネル別詳細 合計行
A15: 再生数合計 | B15: =チャンネル別詳細!C11 -> 481796 | C15: 同上
A16: 登録者合計 | B16: =チャンネル別詳細!E11 -> 260 | C16: 同上
A17: 登録/千再生（全期間） | B17: =チャンネル別詳細!F11 -> 0.53964749 | C17: 同上 | D17: 至上目標の効率指標
A18: 登録/千再生（直近14日） | B18: =チャンネル別詳細!J11 -> 0.68516155 | C18: 同上 | D18: 全期間より高ければ改善方向
A19: 直近14日 / 全期間 | B19: =チャンネル別詳細!L11 -> 1.2696465 | C19: 同上 | D19: 1.00 超で改善
A20: 高評価率（全期間） | B20: =チャンネル別詳細!G11 -> 0.41407567 | C20: 同上 | D20: 登録の主説明変数
A21: 最良チャンネル（登録/千・全期間） | B21: =INDEX(チャンネル別詳細!A5:A10,MATCH(MAX(チャンネル別詳細!F5:F10),チャンネル別詳細!F5:F10,0)) -> scp-lab | C21: チャンネル別詳細
A22: 最弱チャンネル（登録/千・全期間） | B22: =INDEX(チャンネル別詳細!A5:A10,MATCH(MIN(チャンネル別詳細!F5:F10),チャンネル別詳細!F5:F10,0)) -> 2ch-matome | C22: チャンネル別詳細
A23: 09-13 以降公開で未計測の動画 | B23: =COUNTA(動画別パフォーマンス!D524:D604) -> 34 | C23: 動画別パフォーマンス 下段 | D23: 計測待ち。評価に使えない
A24: OAuth 失効中の ch 数 | B24: =COUNTIF(トレンド!E:E,"失効（要再認可）") -> 6 | C24: トレンド | D24: 公開に到達できない
A25: 本日の未完了アクション数 | B25: =COUNTIF(改善アクション!F:F,"未着手") -> 6 | C25: 改善アクション | D25: すべて人手でしか動かせない
A28: 本日のコンフィグ変更（適用済）
A29: チャンネル | B29: 変更内容
A30: 2ch-matome | B30: autopilot.enabled false → true（トークン生存を確認・1日3枠）／評価期日 09-17 → 09-23／維持率メモ更新
A31: daily-science | B31: 評価期日 09-17 → 09-23／維持率メモ更新
A32: scp-lab | B32: 評価期日 09-17 → 09-23／維持率メモ更新
A33: pokemon-lab | B33: 評価期日 09-17 → 09-23／維持率メモ更新（autopilot は OAuth 失効中のため false のまま）
A34: company-facts | B34: 評価期日 09-17 → 09-23／維持率メモ更新
A35: yokai-watch | B35: 維持率メモ更新（09-17 の記載は元から無し）
A36: （変更なし） | B36: 投稿枠 / タイトル型ルール / voice_style / テーマキュー補充 — 理由は改善アクション #8・#9 と、キュー在庫が 28〜34 件（9〜11 日分）あること

Sheet チャンネル別詳細
A1: チャンネル別詳細（全期間 / 直近14日）
A2: すべて「動画別パフォーマンス」シートを SUMIFS で集計した数式。登録/千再生 = 登録者合計 ÷ 再生数合計 × 1000（動画ごとの比の平均ではない）。至上目標は登録者数なので、この列で順位を付けている。
A4: チャンネル | B4: 本数 | C4: 再生数合計 | D4: 平均再生 | E4: 登録者合計 | F4: 登録/千再生 | G4: 高評価率(%) | H4: 平均維持率(%) | I4: 直近14日 本数 | J4: 直近14日 登録/千 | K4: 直近14日 高評価率(%) | L4: 全期間比
A5: scp-lab | B5: =COUNTIFS(動画別パフォーマンス!$A$5:$A$517,A5) -> 160 | C5: =SUMIFS(動画別パフォーマンス!$E$5:$E$517,動画別パフォーマンス!$A$5:$A$517,A5) -> 126981 | D5: =IFERROR(C5/B5,0) -> 793.63125 | E5: =SUMIFS(動画別パフォーマンス!$L$5:$L$517,動画別パフォーマンス!$A$5:$A$517,A5) -> 110 | F5: =IFERROR(E5/C5*1000,0) -> 0.86627133 | G5: =IFERROR(SUMIFS(動画別パフォーマンス!$J$5:$J$517,動画別パフォーマンス!$A$5:$A$517,A5)/C5*100,0) -> 0.45282365 | H5: =IFERROR(SUMPRODUCT((動画別パフォーマンス!$A$5:$A$517=A5)*動画別パフォーマンス!$H$5:$H$517*動画別パフォーマンス!$E$5:$E$517)/C5,0) -> 53.263715 | I5: =COUNTIFS(動画別パフォーマンス!$A$5:$A$517,A5,動画別パフォーマンス!$P$5:$P$517,">=20260902") -> 18 | J5: =IFERROR(SUMIFS(動画別パフォーマンス!$L$5:$L$517,動画別パフォーマンス!$A$5:$A$517,A5,動画別パフォーマンス!$P$5:$P$517,">=20260902")/SUMIFS(動画別パフォーマンス!$E$5:$E$517,動画別パフォーマンス!$A$5:$A$517,A5,動画別パフォーマンス!$P$5:$P$517,">=20260902")*1000,0) -> 0.93585775 | K5: =IFERROR(SUMIFS(動画別パフォーマンス!$J$5:$J$517,動画別パフォーマンス!$A$5:$A$517,A5,動画別パフォーマンス!$P$5:$P$517,">=20260902")/SUMIFS(動画別パフォーマンス!$E$5:$E$517,動画別パフォーマンス!$A$5:$A$517,A5,動画別パフォーマンス!$P$5:$P$517,">=20260902")*100,0) -> 0.4967245 | L5: =IFERROR(J5/F5,0) -> 1.0803287
A6: company-facts | B6: =COUNTIFS(動画別パフォーマンス!$A$5:$A$517,A6) -> 43 | C6: =SUMIFS(動画別パフォーマンス!$E$5:$E$517,動画別パフォーマンス!$A$5:$A$517,A6) -> 55542 | D6: =IFERROR(C6/B6,0) -> 1291.6744 | E6: =SUMIFS(動画別パフォーマンス!$L$5:$L$517,動画別パフォーマンス!$A$5:$A$517,A6) -> 36 | F6: =IFERROR(E6/C6*1000,0) -> 0.64815815 | G6: =IFERROR(SUMIFS(動画別パフォーマンス!$J$5:$J$517,動画別パフォーマンス!$A$5:$A$517,A6)/C6*100,0) -> 0.34568435 | H6: =IFERROR(SUMPRODUCT((動画別パフォーマンス!$A$5:$A$517=A6)*動画別パフォーマンス!$H$5:$H$517*動画別パフォーマンス!$E$5:$E$517)/C6,0) -> 61.342325 | I6: =COUNTIFS(動画別パフォーマンス!$A$5:$A$517,A6,動画別パフォーマンス!$P$5:$P$517,">=20260902") -> 16 | J6: =IFERROR(SUMIFS(動画別パフォーマンス!$L$5:$L$517,動画別パフォーマンス!$A$5:$A$517,A6,動画別パフォーマンス!$P$5:$P$517,">=20260902")/SUMIFS(動画別パフォーマンス!$E$5:$E$517,動画別パフォーマンス!$A$5:$A$517,A6,動画別パフォーマンス!$P$5:$P$517,">=20260902")*1000,0) -> 0.41203131 | K6: =IFERROR(SUMIFS(動画別パフォーマンス!$J$5:$J$517,動画別パフォーマンス!$A$5:$A$517,A6,動画別パフォーマンス!$P$5:$P$517,">=20260902")/SUMIFS(動画別パフォーマンス!$E$5:$E$517,動画別パフォーマンス!$A$5:$A$517,A6,動画別パフォーマンス!$P$5:$P$517,">=20260902")*100,0) -> 0.24133263 | L6: =IFERROR(J6/F6,0) -> 0.63569565
A7: yokai-watch | B7: =COUNTIFS(動画別パフォーマンス!$A$5:$A$517,A7) -> 54 | C7: =SUMIFS(動画別パフォーマンス!$E$5:$E$517,動画別パフォーマンス!$A$5:$A$517,A7) -> 55400 | D7: =IFERROR(C7/B7,0) -> 1025.9259 | E7: =SUMIFS(動画別パフォーマンス!$L$5:$L$517,動画別パフォーマンス!$A$5:$A$517,A7) -> 29 | F7: =IFERROR(E7/C7*1000,0) -> 0.5234657 | G7: =IFERROR(SUMIFS(動画別パフォーマンス!$J$5:$J$517,動画別パフォーマンス!$A$5:$A$517,A7)/C7*100,0) -> 0.45848375 | H7: =IFERROR(SUMPRODUCT((動画別パフォーマンス!$A$5:$A$517=A7)*動画別パフォーマンス!$H$5:$H$517*動画別パフォーマンス!$E$5:$E$517)/C7,0) -> 62.645785 | I7: =COUNTIFS(動画別パフォーマンス!$A$5:$A$517,A7,動画別パフォーマンス!$P$5:$P$517,">=20260902") -> 15 | J7: =IFERROR(SUMIFS(動画別パフォーマンス!$L$5:$L$517,動画別パフォーマンス!$A$5:$A$517,A7,動画別パフォーマンス!$P$5:$P$517,">=20260902")/SUMIFS(動画別パフォーマンス!$E$5:$E$517,動画別パフォーマンス!$A$5:$A$517,A7,動画別パフォーマンス!$P$5:$P$517,">=20260902")*1000,0) -> 1.3069617 | K7: =IFERROR(SUMIFS(動画別パフォーマンス!$J$5:$J$517,動画別パフォーマンス!$A$5:$A$517,A7,動画別パフォーマンス!$P$5:$P$517,">=20260902")/SUMIFS(動画別パフォーマンス!$E$5:$E$517,動画別パフォーマンス!$A$5:$A$517,A7,動画別パフォーマンス!$P$5:$P$517,">=20260902")*100,0) -> 0.82774244 | L7: =IFERROR(J7/F7,0) -> 2.4967476
A8: daily-science | B8: =COUNTIFS(動画別パフォーマンス!$A$5:$A$517,A8) -> 157 | C8: =SUMIFS(動画別パフォーマンス!$E$5:$E$517,動画別パフォーマンス!$A$5:$A$517,A8) -> 140587 | D8: =IFERROR(C8/B8,0) -> 895.4586 | E8: =SUMIFS(動画別パフォーマンス!$L$5:$L$517,動画別パフォーマンス!$A$5:$A$517,A8) -> 57 | F8: =IFERROR(E8/C8*1000,0) -> 0.40544289 | G8: =IFERROR(SUMIFS(動画別パフォーマンス!$J$5:$J$517,動画別パフォーマンス!$A$5:$A$517,A8)/C8*100,0) -> 0.50715927 | H8: =IFERROR(SUMPRODUCT((動画別パフォーマンス!$A$5:$A$517=A8)*動画別パフォーマンス!$H$5:$H$517*動画別パフォーマンス!$E$5:$E$517)/C8,0) -> 83.641841 | I8: =COUNTIFS(動画別パフォーマンス!$A$5:$A$517,A8,動画別パフォーマンス!$P$5:$P$517,">=20260902") -> 15 | J8: =IFERROR(SUMIFS(動画別パフォーマンス!$L$5:$L$517,動画別パフォーマンス!$A$5:$A$517,A8,動画別パフォーマンス!$P$5:$P$517,">=20260902")/SUMIFS(動画別パフォーマンス!$E$5:$E$517,動画別パフォーマンス!$A$5:$A$517,A8,動画別パフォーマンス!$P$5:$P$517,">=20260902")*1000,0) -> 0.68115251 | K8: =IFERROR(SUMIFS(動画別パフォーマンス!$J$5:$J$517,動画別パフォーマンス!$A$5:$A$517,A8,動画別パフォーマンス!$P$5:$P$517,">=20260902")/SUMIFS(動画別パフォーマンス!$E$5:$E$517,動画別パフォーマンス!$A$5:$A$517,A8,動画別パフォーマンス!$P$5:$P$517,">=20260902")*100,0) -> 0.91274436 | L8: =IFERROR(J8/F8,0) -> 1.6800208
A9: pokemon-lab | B9: =COUNTIFS(動画別パフォーマンス!$A$5:$A$517,A9) -> 48 | C9: =SUMIFS(動画別パフォーマンス!$E$5:$E$517,動画別パフォーマンス!$A$5:$A$517,A9) -> 55667 | D9: =IFERROR(C9/B9,0) -> 1159.7292 | E9: =SUMIFS(動画別パフォーマンス!$L$5:$L$517,動画別パフォーマンス!$A$5:$A$517,A9) -> 19 | F9: =IFERROR(E9/C9*1000,0) -> 0.34131532 | G9: =IFERROR(SUMIFS(動画別パフォーマンス!$J$5:$J$517,動画別パフォーマンス!$A$5:$A$517,A9)/C9*100,0) -> 0.28562703 | H9: =IFERROR(SUMPRODUCT((動画別パフォーマンス!$A$5:$A$517=A9)*動画別パフォーマンス!$H$5:$H$517*動画別パフォーマンス!$E$5:$E$517)/C9,0) -> 62.22735 | I9: =COUNTIFS(動画別パフォーマンス!$A$5:$A$517,A9,動画別パフォーマンス!$P$5:$P$517,">=20260902") -> 8 | J9: =IFERROR(SUMIFS(動画別パフォーマンス!$L$5:$L$517,動画別パフォーマンス!$A$5:$A$517,A9,動画別パフォーマンス!$P$5:$P$517,">=20260902")/SUMIFS(動画別パフォーマンス!$E$5:$E$517,動画別パフォーマンス!$A$5:$A$517,A9,動画別パフォーマンス!$P$5:$P$517,">=20260902")*1000,0) -> 0.54190751 | K9: =IFERROR(SUMIFS(動画別パフォーマンス!$J$5:$J$517,動画別パフォーマンス!$A$5:$A$517,A9,動画別パフォーマンス!$P$5:$P$517,">=20260902")/SUMIFS(動画別パフォーマンス!$E$5:$E$517,動画別パフォーマンス!$A$5:$A$517,A9,動画別パフォーマンス!$P$5:$P$517,">=20260902")*100,0) -> 0.18063584 | L9: =IFERROR(J9/F9,0) -> 1.5877035
A10: 2ch-matome | B10: =COUNTIFS(動画別パフォーマンス!$A$5:$A$517,A10) -> 51 | C10: =SUMIFS(動画別パフォーマンス!$E$5:$E$517,動画別パフォーマンス!$A$5:$A$517,A10) -> 47619 | D10: =IFERROR(C10/B10,0) -> 933.70588 | E10: =SUMIFS(動画別パフォーマンス!$L$5:$L$517,動画別パフォーマンス!$A$5:$A$517,A10) -> 9 | F10: =IFERROR(E10/C10*1000,0) -> 0.18900019 | G10: =IFERROR(SUMIFS(動画別パフォーマンス!$J$5:$J$517,動画別パフォーマンス!$A$5:$A$517,A10)/C10*100,0) -> 0.21420021 | H10: =IFERROR(SUMPRODUCT((動画別パフォーマンス!$A$5:$A$517=A10)*動画別パフォーマンス!$H$5:$H$517*動画別パフォーマンス!$E$5:$E$517)/C10,0) -> 50.153972 | I10: =COUNTIFS(動画別パフォーマンス!$A$5:$A$517,A10,動画別パフォーマンス!$P$5:$P$517,">=20260902") -> 16 | J10: =IFERROR(SUMIFS(動画別パフォーマンス!$L$5:$L$517,動画別パフォーマンス!$A$5:$A$517,A10,動画別パフォーマンス!$P$5:$P$517,">=20260902")/SUMIFS(動画別パフォーマンス!$E$5:$E$517,動画別パフォーマンス!$A$5:$A$517,A10,動画別パフォーマンス!$P$5:$P$517,">=20260902")*1000,0) -> 0.25292977 | K10: =IFERROR(SUMIFS(動画別パフォーマンス!$J$5:$J$517,動画別パフォーマンス!$A$5:$A$517,A10,動画別パフォーマンス!$P$5:$P$517,">=20260902")/SUMIFS(動画別パフォーマンス!$E$5:$E$517,動画別パフォーマンス!$A$5:$A$517,A10,動画別パフォーマンス!$P$5:$P$517,">=20260902")*100,0) -> 0.10117191 | L10: =IFERROR(J10/F10,0) -> 1.3382514
A11: 合計 | B11: =SUM(B5:B10) -> 513 | C11: =SUM(C5:C10) -> 481796 | D11: =IFERROR(C11/B11,0) -> 939.17349 | E11: =SUM(E5:E10) -> 260 | F11: =IFERROR(E11/C11*1000,0) -> 0.53964749 | G11: =IFERROR(SUM(動画別パフォーマンス!$J$5:$J$517)/C11*100,0) -> 0.41407567 | H11: =IFERROR(SUMPRODUCT(動画別パフォーマンス!$H$5:$H$517,動画別パフォーマンス!$E$5:$E$517)/C11,0) -> 64.866414 | I11: =SUM(I5:I10) -> 88 | J11: =IFERROR(SUMIFS(動画別パフォーマンス!$L$5:$L$517,動画別パフォーマンス!$P$5:$P$517,">=20260902")/SUMIFS(動画別パフォーマンス!$E$5:$E$517,動画別パフォーマンス!$P$5:$P$517,">=20260902")*1000,0) -> 0.68516155 | K11: =IFERROR(SUMIFS(動画別パフォーマンス!$J$5:$J$517,動画別パフォーマンス!$P$5:$P$517,">=20260902")/SUMIFS(動画別パフォーマンス!$E$5:$E$517,動画別パフォーマンス!$P$5:$P$517,">=20260902")*100,0) -> 0.4849869 | L11: =IFERROR(J11/F11,0) -> 1.2696465
A14: 維持率バンド別 登録効率（公開 2026-08-01 以降・200再生以上）
A15: 09-15 に記録した「70%以上が最下位（0.294）」は本日の再集計で 0.471 となり再現しなかった。頂点が 40-50% 帯であることだけが再現している。
A17: 維持率バンド | B17: 本数 | C17: 再生数 | D17: 登録者 | E17: 登録/千再生 | F17: 高評価率(%)
A18: 00-30 | B18: =COUNTIFS(動画別パフォーマンス!$O$5:$O$517,A18,動画別パフォーマンス!$E$5:$E$517,">=200",動画別パフォーマンス!$P$5:$P$517,">=20260801") -> 26 | C18: =SUMIFS(動画別パフォーマンス!$E$5:$E$517,動画別パフォーマンス!$O$5:$O$517,A18,動画別パフォーマンス!$E$5:$E$517,">=200",動画別パフォーマンス!$P$5:$P$517,">=20260801") -> 23383 | D18: =SUMIFS(動画別パフォーマンス!$L$5:$L$517,動画別パフォーマンス!$O$5:$O$517,A18,動画別パフォーマンス!$E$5:$E$517,">=200",動画別パフォーマンス!$P$5:$P$517,">=20260801") -> 6 | E18: =IFERROR(D18/C18*1000,0) -> 0.25659667 | F18: =IFERROR(SUMIFS(動画別パフォーマンス!$J$5:$J$517,動画別パフォーマンス!$O$5:$O$517,A18,動画別パフォーマンス!$E$5:$E$517,">=200",動画別パフォーマンス!$P$5:$P$517,">=20260801")/C18*100,0) -> 0.32929906
A19: 30-40 | B19: =COUNTIFS(動画別パフォーマンス!$O$5:$O$517,A19,動画別パフォーマンス!$E$5:$E$517,">=200",動画別パフォーマンス!$P$5:$P$517,">=20260801") -> 67 | C19: =SUMIFS(動画別パフォーマンス!$E$5:$E$517,動画別パフォーマンス!$O$5:$O$517,A19,動画別パフォーマンス!$E$5:$E$517,">=200",動画別パフォーマンス!$P$5:$P$517,">=20260801") -> 58229 | D19: =SUMIFS(動画別パフォーマンス!$L$5:$L$517,動画別パフォーマンス!$O$5:$O$517,A19,動画別パフォーマンス!$E$5:$E$517,">=200",動画別パフォーマンス!$P$5:$P$517,">=20260801") -> 30 | E19: =IFERROR(D19/C19*1000,0) -> 0.5152072 | F19: =IFERROR(SUMIFS(動画別パフォーマンス!$J$5:$J$517,動画別パフォーマンス!$O$5:$O$517,A19,動画別パフォーマンス!$E$5:$E$517,">=200",動画別パフォーマンス!$P$5:$P$517,">=20260801")/C19*100,0) -> 0.37781861
A20: 40-50 | B20: =COUNTIFS(動画別パフォーマンス!$O$5:$O$517,A20,動画別パフォーマンス!$E$5:$E$517,">=200",動画別パフォーマンス!$P$5:$P$517,">=20260801") -> 68 | C20: =SUMIFS(動画別パフォーマンス!$E$5:$E$517,動画別パフォーマンス!$O$5:$O$517,A20,動画別パフォーマンス!$E$5:$E$517,">=200",動画別パフォーマンス!$P$5:$P$517,">=20260801") -> 64826 | D20: =SUMIFS(動画別パフォーマンス!$L$5:$L$517,動画別パフォーマンス!$O$5:$O$517,A20,動画別パフォーマンス!$E$5:$E$517,">=200",動画別パフォーマンス!$P$5:$P$517,">=20260801") -> 44 | E20: =IFERROR(D20/C20*1000,0) -> 0.67874001 | F20: =IFERROR(SUMIFS(動画別パフォーマンス!$J$5:$J$517,動画別パフォーマンス!$O$5:$O$517,A20,動画別パフォーマンス!$E$5:$E$517,">=200",動画別パフォーマンス!$P$5:$P$517,">=20260801")/C20*100,0) -> 0.48283096
A21: 50-60 | B21: =COUNTIFS(動画別パフォーマンス!$O$5:$O$517,A21,動画別パフォーマンス!$E$5:$E$517,">=200",動画別パフォーマンス!$P$5:$P$517,">=20260801") -> 56 | C21: =SUMIFS(動画別パフォーマンス!$E$5:$E$517,動画別パフォーマンス!$O$5:$O$517,A21,動画別パフォーマンス!$E$5:$E$517,">=200",動画別パフォーマンス!$P$5:$P$517,">=20260801") -> 65956 | D21: =SUMIFS(動画別パフォーマンス!$L$5:$L$517,動画別パフォーマンス!$O$5:$O$517,A21,動画別パフォーマンス!$E$5:$E$517,">=200",動画別パフォーマンス!$P$5:$P$517,">=20260801") -> 34 | E21: =IFERROR(D21/C21*1000,0) -> 0.51549518 | F21: =IFERROR(SUMIFS(動画別パフォーマンス!$J$5:$J$517,動画別パフォーマンス!$O$5:$O$517,A21,動画別パフォーマンス!$E$5:$E$517,">=200",動画別パフォーマンス!$P$5:$P$517,">=20260801")/C21*100,0) -> 0.36842744
A22: 60-70 | B22: =COUNTIFS(動画別パフォーマンス!$O$5:$O$517,A22,動画別パフォーマンス!$E$5:$E$517,">=200",動画別パフォーマンス!$P$5:$P$517,">=20260801") -> 33 | C22: =SUMIFS(動画別パフォーマンス!$E$5:$E$517,動画別パフォーマンス!$O$5:$O$517,A22,動画別パフォーマンス!$E$5:$E$517,">=200",動画別パフォーマンス!$P$5:$P$517,">=20260801") -> 40015 | D22: =SUMIFS(動画別パフォーマンス!$L$5:$L$517,動画別パフォーマンス!$O$5:$O$517,A22,動画別パフォーマンス!$E$5:$E$517,">=200",動画別パフォーマンス!$P$5:$P$517,">=20260801") -> 17 | E22: =IFERROR(D22/C22*1000,0) -> 0.42484068 | F22: =IFERROR(SUMIFS(動画別パフォーマンス!$J$5:$J$517,動画別パフォーマンス!$O$5:$O$517,A22,動画別パフォーマンス!$E$5:$E$517,">=200",動画別パフォーマンス!$P$5:$P$517,">=20260801")/C22*100,0) -> 0.3498688
A23: 70+ | B23: =COUNTIFS(動画別パフォーマンス!$O$5:$O$517,A23,動画別パフォーマンス!$E$5:$E$517,">=200",動画別パフォーマンス!$P$5:$P$517,">=20260801") -> 48 | C23: =SUMIFS(動画別パフォーマンス!$E$5:$E$517,動画別パフォーマンス!$O$5:$O$517,A23,動画別パフォーマンス!$E$5:$E$517,">=200",動画別パフォーマンス!$P$5:$P$517,">=20260801") -> 61530 | D23: =SUMIFS(動画別パフォーマンス!$L$5:$L$517,動画別パフォーマンス!$O$5:$O$517,A23,動画別パフォーマンス!$E$5:$E$517,">=200",動画別パフォーマンス!$P$5:$P$517,">=20260801") -> 29 | E23: =IFERROR(D23/C23*1000,0) -> 0.47131481 | F23: =IFERROR(SUMIFS(動画別パフォーマンス!$J$5:$J$517,動画別パフォーマンス!$O$5:$O$517,A23,動画別パフォーマンス!$E$5:$E$517,">=200",動画別パフォーマンス!$P$5:$P$517,">=20260801")/C23*100,0) -> 0.38680319
A26: 高評価率と登録効率の関係（最も頑健な所見・6回目の再現）
A27: 200再生以上 n=474 を高評価率で四分位に分けると、登録/千再生が単調に増える。維持率・再生数にはこの単調性が無い。改善の主レバーは高評価率である。
A29: 高評価率 四分位 | B29: 境界(%) | C29: 本数 | D29: 再生数 | E29: 登録者 | F29: 登録/千再生
A30: Q1(低) | B30: 0.000 〜 0.209 | C30: =COUNTIFS(動画別パフォーマンス!$N$5:$N$517,">=0.0",動画別パフォーマンス!$N$5:$N$517,"<0.2086",動画別パフォーマンス!$E$5:$E$517,">=200") -> 119 | D30: =SUMIFS(動画別パフォーマンス!$E$5:$E$517,動画別パフォーマンス!$N$5:$N$517,">=0.0",動画別パフォーマンス!$N$5:$N$517,"<0.2086",動画別パフォーマンス!$E$5:$E$517,">=200") -> 109860 | E30: =SUMIFS(動画別パフォーマンス!$L$5:$L$517,動画別パフォーマンス!$N$5:$N$517,">=0.0",動画別パフォーマンス!$N$5:$N$517,"<0.2086",動画別パフォーマンス!$E$5:$E$517,">=200") -> 30 | F30: =IFERROR(E30/D30*1000,0) -> 0.27307482
A31: Q2 | B31: 0.209 〜 0.366 | C31: =COUNTIFS(動画別パフォーマンス!$N$5:$N$517,">=0.2086",動画別パフォーマンス!$N$5:$N$517,"<0.366",動画別パフォーマンス!$E$5:$E$517,">=200") -> 117 | D31: =SUMIFS(動画別パフォーマンス!$E$5:$E$517,動画別パフォーマンス!$N$5:$N$517,">=0.2086",動画別パフォーマンス!$N$5:$N$517,"<0.366",動画別パフォーマンス!$E$5:$E$517,">=200") -> 130017 | E31: =SUMIFS(動画別パフォーマンス!$L$5:$L$517,動画別パフォーマンス!$N$5:$N$517,">=0.2086",動画別パフォーマンス!$N$5:$N$517,"<0.366",動画別パフォーマンス!$E$5:$E$517,">=200") -> 56 | F31: =IFERROR(E31/D31*1000,0) -> 0.43071291
A32: Q3 | B32: 0.366 〜 0.572 | C32: =COUNTIFS(動画別パフォーマンス!$N$5:$N$517,">=0.366",動画別パフォーマンス!$N$5:$N$517,"<0.572",動画別パフォーマンス!$E$5:$E$517,">=200") -> 119 | D32: =SUMIFS(動画別パフォーマンス!$E$5:$E$517,動画別パフォーマンス!$N$5:$N$517,">=0.366",動画別パフォーマンス!$N$5:$N$517,"<0.572",動画別パフォーマンス!$E$5:$E$517,">=200") -> 125415 | E32: =SUMIFS(動画別パフォーマンス!$L$5:$L$517,動画別パフォーマンス!$N$5:$N$517,">=0.366",動画別パフォーマンス!$N$5:$N$517,"<0.572",動画別パフォーマンス!$E$5:$E$517,">=200") -> 64 | F32: =IFERROR(E32/D32*1000,0) -> 0.51030578
A33: Q4(高) | B33: 0.572 〜 100.000 | C33: =COUNTIFS(動画別パフォーマンス!$N$5:$N$517,">=0.572",動画別パフォーマンス!$N$5:$N$517,"<=100.0",動画別パフォーマンス!$E$5:$E$517,">=200") -> 119 | D33: =SUMIFS(動画別パフォーマンス!$E$5:$E$517,動画別パフォーマンス!$N$5:$N$517,">=0.572",動画別パフォーマンス!$N$5:$N$517,"<=100.0",動画別パフォーマンス!$E$5:$E$517,">=200") -> 113248 | E33: =SUMIFS(動画別パフォーマンス!$L$5:$L$517,動画別パフォーマンス!$N$5:$N$517,">=0.572",動画別パフォーマンス!$N$5:$N$517,"<=100.0",動画別パフォーマンス!$E$5:$E$517,">=200") -> 107 | F33: =IFERROR(E33/D33*1000,0) -> 0.94482905

Sheet 動画別パフォーマンス
A1: 動画別パフォーマンス（moviepy 6ch・views>0 のみ・video_id で畳んだ最大値）
A2: 出典: data/analytics/analytics.db（最終同期 2026-09-15 22:41）。1動画につき複数日のスナップショットがあるため video_id ごとに最大値を採用。E〜L 列は DB の実測値、M〜O 列は数式。
A4: チャンネル | B4: 公開日 | C4: タイトル | D4: 動画ID | E4: 再生数 | F4: インプレッション | G4: CTR(%) | H4: 維持率(%) | I4: 平均視聴秒 | J4: 高評価 | K4: コメント | L4: 登録者 | M4: 登録/千再生 | N4: 高評価率(%) | O4: 維持率バンド | P4: 公開日key
A5: 2ch-matome | B5: 2026-08-09 | C5: 30秒スレまとめ：残業代はやる気で払う#上司「残業代はやる気で払う」発言から、なぜか全員消えた職場の末路 #shorts #ゆっくり解説 | D5: WtRQk1PvOKM | E5: 1364 | F5: 50 | G5: 0.114 | H5: 48.36 | I5: 12 | J5: 3 | K5: 0 | L5: 0 | M5: =IFERROR(L5/E5*1000,0) -> 0 | N5: =IFERROR(J5/E5*100,0) -> 0.21994135 | O5: =IF(H5<30,"00-30",IF(H5<40,"30-40",IF(H5<50,"40-50",IF(H5<60,"50-60",IF(H5<70,"60-70","70+"))))) -> 40-50 | P5: =IFERROR(VALUE(SUBSTITUTE(B5,"-","")),0) -> 20260809
A6: 2ch-matome | B6: 2026-08-13 | C6: コンビニで一番いらん商品あげてけ【ショート】 | D6: MASXwV-ZkDc | E6: 1086 | F6: 36 | G6: 0.036 | H6: 125.51 | I6: 28 | J6: 1 | K6: 0 | L6: 0 | M6: =IFERROR(L6/E6*1000,0) -> 0 | N6: =IFERROR(J6/E6*100,0) -> 0.092081031 | O6: =IF(H6<30,"00-30",IF(H6<40,"30-40",IF(H6<50,"40-50",IF(H6<60,"50-60",IF(H6<70,"60-70","70+"))))) -> 70+ | P6: =IFERROR(VALUE(SUBSTITUTE(B6,"-","")),0) -> 20260813
A7: 2ch-matome | B7: 2026-08-13 | C7: ワイの今日の昼飯を当てるスレw【ショート】 | D7: WJpTwtFMnTM | E7: 1439 | F7: 58 | G7: 0.043 | H7: 66.69 | I7: 14 | J7: 3 | K7: 0 | L7: 0 | M7: =IFERROR(L7/E7*1000,0) -> 0 | N7: =IFERROR(J7/E7*100,0) -> 0.20847811 | O7: =IF(H7<30,"00-30",IF(H7<40,"30-40",IF(H7<50,"40-50",IF(H7<60,"50-60",IF(H7<70,"60-70","70+"))))) -> 60-70 | P7: =IFERROR(VALUE(SUBSTITUTE(B7,"-","")),0) -> 20260813
A8: 2ch-matome | B8: 2026-08-14 | C8: なんかPCの画面チカチカするんやが【ショート】 | D8: WDnmFqiOqpU | E8: 1319 | F8: 81 | G8: 0.037 | H8: 61.41 | I8: 14 | J8: 4 | K8: 0 | L8: 2 | M8: =IFERROR(L8/E8*1000,0) -> 1.5163002 | N8: =IFERROR(J8/E8*100,0) -> 0.30326005 | O8: =IF(H8<30,"00-30",IF(H8<40,"30-40",IF(H8<50,"40-50",IF(H8<60,"50-60",IF(H8<70,"60-70","70+"))))) -> 60-70 | P8: =IFERROR(VALUE(SUBSTITUTE(B8,"-","")),0) -> 20260814
A9: 2ch-matome | B9: 2026-08-14 | C9: 彼女の部屋でヤバい物あげてけw【ショート】 | D9: vkhUIYYCiJ8 | E9: 1368 | F9: 33 | G9: 0 | H9: 49.89 | I9: 11 | J9: 3 | K9: 0 | L9: 1 | M9: =IFERROR(L9/E9*1000,0) -> 0.73099415 | N9: =IFERROR(J9/E9*100,0) -> 0.21929825 | O9: =IF(H9<30,"00-30",IF(H9<40,"30-40",IF(H9<50,"40-50",IF(H9<60,"50-60",IF(H9<70,"60-70","70+"))))) -> 40-50 | P9: =IFERROR(VALUE(SUBSTITUTE(B9,"-","")),0) -> 20260814
A10: 2ch-matome | B10: 2026-08-15 | C10: ワイ、彼女いない歴＝年齢やけど質問ある？【ショート】 | D10: Be4FYVfZ57Y | E10: 1656 | F10: 35 | G10: 0.111 | H10: 64.42 | I10: 15 | J10: 4 | K10: 2 | L10: 0 | M10: =IFERROR(L10/E10*1000,0) -> 0 | N10: =IFERROR(J10/E10*100,0) -> 0.24154589 | O10: =IF(H10<30,"00-30",IF(H10<40,"30-40",IF(H10<50,"40-50",IF(H10<60,"50-60",IF(H10<70,"60-70","70+"))))) -> 60-70 | P10: =IFERROR(VALUE(SUBSTITUTE(B10,"-","")),0) -> 20260815
A11: 2ch-matome | B11: 2026-08-15 | C11: ワイのキーボードの変な癖あげてけw【ショート】 | D11: prWmOE1LGbQ | E11: 1191 | F11: 25 | G11: 0 | H11: 51.28 | I11: 11 | J11: 0 | K11: 0 | L11: 0 | M11: =IFERROR(L11/E11*1000,0) -> 0 | N11: =IFERROR(J11/E11*100,0) -> 0 | O11: =IF(H11<30,"00-30",IF(H11<40,"30-40",IF(H11<50,"40-50",IF(H11<60,"50-60",IF(H11<70,"60-70","70+"))))) -> 50-60 | P11: =IFERROR(VALUE(SUBSTITUTE(B11,"-","")),0) -> 20260815
A12: 2ch-matome | B12: 2026-08-16 | C12: なんかスマホの充電だけ遅いんやが【ショート】 | D12: 0lc5Rc36_Dc | E12: 1355 | F12: 31 | G12: 0 | H12: 72.17 | I12: 16 | J12: 1 | K12: 1 | L12: 0 | M12: =IFERROR(L12/E12*1000,0) -> 0 | N12: =IFERROR(J12/E12*100,0) -> 0.073800738 | O12: =IF(H12<30,"00-30",IF(H12<40,"30-40",IF(H12<50,"40-50",IF(H12<60,"50-60",IF(H12<70,"60-70","70+"))))) -> 70+ | P12: =IFERROR(VALUE(SUBSTITUTE(B12,"-","")),0) -> 20260816
A13: 2ch-matome | B13: 2026-08-17 | C13: 後輩「敬語って課金制ですよね？」→翌朝、全員が黙った #shorts #2ch #スカッと | D13: 0xBt5Iu6AgA | E13: 1355 | F13: 35 | G13: 0 | H13: 57.22 | I13: 16 | J13: 4 | K13: 0 | L13: 0 | M13: =IFERROR(L13/E13*1000,0) -> 0 | N13: =IFERROR(J13/E13*100,0) -> 0.29520295 | O13: =IF(H13<30,"00-30",IF(H13<40,"30-40",IF(H13<50,"40-50",IF(H13<60,"50-60",IF(H13<70,"60-70","70+"))))) -> 50-60 | P13: =IFERROR(VALUE(SUBSTITUTE(B13,"-","")),0) -> 20260817
A14: 2ch-matome | B14: 2026-08-17 | C14: 実際には存在しないけどありそうな県名あげてけ【ショート】 | D14: 9TEBWzcaEkg | E14: 1162 | F14: 30 | G14: 0 | H14: 109.6 | I14: 28 | J14: 3 | K14: 0 | L14: 0 | M14: =IFERROR(L14/E14*1000,0) -> 0 | N14: =IFERROR(J14/E14*100,0) -> 0.25817556 | O14: =IF(H14<30,"00-30",IF(H14<40,"30-40",IF(H14<50,"40-50",IF(H14<60,"50-60",IF(H14<70,"60-70","70+"))))) -> 70+ | P14: =IFERROR(VALUE(SUBSTITUTE(B14,"-","")),0) -> 20260817
A15: 2ch-matome | B15: 2026-08-17 | C15: 飲み会で絶対見られたくない通知あげてけw【ショート】 | D15: RNnXuVaiEDQ | E15: 2 | F15: 24 | G15: 0 | H15: 33.83 | I15: 7 | J15: 0 | K15: 0 | L15: 0 | M15: =IFERROR(L15/E15*1000,0) -> 0 | N15: =IFERROR(J15/E15*100,0) -> 0 | O15: =IF(H15<30,"00-30",IF(H15<40,"30-40",IF(H15<50,"40-50",IF(H15<60,"50-60",IF(H15<70,"60-70","70+"))))) -> 30-40 | P15: =IFERROR(VALUE(SUBSTITUTE(B15,"-","")),0) -> 20260817
A16: 2ch-matome | B16: 2026-08-17 | C16: ワイ、AIに変な質問する係やけど質問ある？w【ショート】 | D16: kFxWX6wPLxA | E16: 1 | F16: 33 | G16: 0 | H16: 80.8 | I16: 20 | J16: 0 | K16: 0 | L16: 0 | M16: =IFERROR(L16/E16*1000,0) -> 0 | N16: =IFERROR(J16/E16*100,0) -> 0 | O16: =IF(H16<30,"00-30",IF(H16<40,"30-40",IF(H16<50,"40-50",IF(H16<60,"50-60",IF(H16<70,"60-70","70+"))))) -> 70+ | P16: =IFERROR(VALUE(SUBSTITUTE(B16,"-","")),0) -> 20260817
... A517: yokai-watch | B517: 2026-09-08 | C517: ろくろ首の正体は飛頭蛮？首が飛ぶ怪異の出どころ #shorts #妖怪 #都市伝説 | D517: oUohYkADVPs | E517: 1100 | F517: 491 | G517: 0.022 | H517: 44.45 | I517: 15 | J517: 6 | K517: 1 | L517: 1 | M517: =IFERROR(L517/E517*1000,0) -> 0.90909091 | N517: =IFERROR(J517/E517*100,0) -> 0.54545455 | O517: =IF(H517<30,"00-30",IF(H517<40,"30-40",IF(H517<50,"40-50",IF(H517<60,"50-60",IF(H517<70,"60-70","70+"))))) -> 40-50 | P517: =IFERROR(VALUE(SUBSTITUTE(B517,"-","")),0) -> 20260908
A520: 【参考】09-13 以降に公開したが analytics でまだ計測されていない動画
A521: YouTube Analytics の反映は公開からおよそ 2 日遅れる（09-13 公開の scp-lab は 09-15 スナップショットで初めて views>0 になった）。下記は本日時点で評価に使えない。
A523: チャンネル | B523: 公開日 | C523: タイトル | D523: 動画ID
A524: company-facts | B524: 2026-09-13 | C524: ワークマンが一般客を呼んだ転機、売上1,283億円の裏側 #shorts #企業分析 #年収 #転職 | D524: NcHi0GOCZbI
A525: company-facts | B525: 2026-09-13 | C525: コメダ珈琲がFC比率99%にする本当の理由とは #shorts #企業分析 #年収 #転職 | D525: fnSd_UevV9Y
A526: company-facts | B526: 2026-09-13 | C526: スシローが回転をやめた店を増やす3業態の狙い実態 #shorts #企業分析 #年収 #転職 | D526: yduOYRCbeV0
A527: daily-science | B527: 2026-09-13 | C527: なぜあなたはくしゃみの3秒前を予感するのか？本当の正体 #shorts #雑学 #豆知識 | D527: npZgeGUSuyU
A528: daily-science | B528: 2026-09-13 | C528: なぜ海で沖へ運ばれる？毎秒1mの流れの正体 #shorts #雑学 #豆知識 | D528: vCgLfbgThF4
A529: scp-lab | B529: 2026-09-13 | C529: SCP-7777が72時間で窓へ接近する理由 #shorts #SCP #SCP解説 | D529: ZVKUKGZ0sjs
A530: yokai-watch | B530: 2026-09-13 | C530: 雷獣の爪痕が落雷木に残る…江戸で剥製まで売られた怪異の正体 #shorts #妖怪 #都市伝説 | D530: 5It8viRoqko
A531: company-facts | B531: 2026-09-14 | C531: ニトリ864万円の裏側、配置転換が生む働き方のリアル #shorts #企業分析 #年収 #転職 | D531: 6rsFuGUVMpY
A532: company-facts | B532: 2026-09-14 | C532: 任天堂の年収986万円、実は職種で差が出る #shorts #企業分析 #年収 #転職 | D532: CUEt-Rv-cbw
A533: company-facts | B533: 2026-09-14 | C533: USJの年収と福利厚生、その実態とは？人気の裏側を暴露 #shorts #企業分析 #年収 #転職 | D533: MRVrclIIzEo
A534: company-facts | B534: 2026-09-14 | C534: 味の素の給与1065万円、手当だけではない本当の理由 #shorts #企業分析 #年収 #転職 | D534: VynYTrRWhZ8
... A557: yokai-watch | B557: 2026-09-15 | C557: 天井なめが座敷にだけ現れた理由と囲炉裏の煤の関係 #shorts #妖怪 #都市伝説 | D557: vRcT10h0_a4

Sheet 改善アクション
A1: 改善アクション — 2026-09-16
A2: 実行者が「人」の項目は指揮者では動かせない。至上目標（チャンネル登録者数）への効き目が大きい順に並べてある。
A4: # | B4: アクション | C4: 根拠（実データ） | D4: 効き目 | E4: 実行者 | F4: 状態 | G4: 期日
A5: 1 | B5: Google OAuth 同意画面を「テスト」から「本番環境」へ公開する | C5: 09-09〜09-12 に公開が 33本/日 → 0〜2本/日 へ全停止。原因は全 ch のリフレッシュトークン一斉失効。失効 6ch の最終リフレッシュは 7.5〜9.5 日前に固まっており、テスト公開時の 7 日寿命と一致する。09-13 に再認可した 6ch も同じ寿命なら 09-20 前後に再失効する。 | D5: 最大（停止1回あたり約 100 本 ≒ 60 人分の公開機会） | E5: 人 | F5: 未着手 | G5: 至急
A6: 2 | B6: 失効 6ch（clip-lab / clip-kaneko / clip-fukada / akashic-librarian / fake-paper / clip-animal）と pokemon-lab を再認可する | C6: oauth_health_check.py: 6ch が 7.5〜9.5 日経過で失効、pokemon-lab は 6.1 日で警告。この 7ch は 09-10 以降 1 本も公開していない。 | D6: 大（13ch 中 7ch が停止中） | E6: 人 | F6: 未着手 | G6: 至急（#1 の後）
A7: 3 | B7: サムネイル権限の 403 を解消する（YouTube の電話番号確認） | C7: 09-16 の公開でも scp-lab / company-facts / yokai-watch は全件 403。成功しているのは daily-science のみ。4 日連続で未解決。pokemon-lab は browse/suggested CTR 0.69% で 6ch 最低であり、サムネが当 ch の最大のボトルネックと特定済み。 | D7: 大（CTR 経由で全 ch に効く） | E7: 人 | F7: 未着手 | G7: 至急
A8: 4 | B8: Anthropic API キーを差し替える | C8: backend.log: claude_client call failed (thumbnail_brief) 401。連動して series_engine が全 ch で「Claude 未応答のため続編候補を生成しません」。サムネ指示文と続編候補が両方止まっている。 | D8: 中 | E8: 人 | F8: 未着手 | G8: 至急
A9: 5 | B9: 2ch-matome の autopilot を再開した（本日実施） | C9: youtube_tokens.db の最終リフレッシュ成功が 09-15 22:30 で当 ch のトークンは生存。トークンが生きているのに autopilot=false なのは当 ch だけだった。1日3枠 = 約 +0.7 登録/日。 | D9: 小（+0.7 登録/日） | E9: 指揮者 | F9: 適用済 | G9: 2026-09-16
A10: 6 | B10: バックエンドを 1 回再起動する | C10: APScheduler のジョブ登録は restore_all() が起動時に data/channels/*.json を読んで行う。#5 の変更は再起動しないと反映されない。 | D10: 小（#5 の前提） | E10: 人 | F10: 未着手 | G10: 本日中
A11: 7 | B11: 09-09〜09-12 の analytics を遡って同期する | C11: video_metrics の date 列に 2026-09-09〜09-12 が 1 行も無い。当該期間に公開した動画は 4 本だけなので損失は小さいが、同期ジョブが止まっても気づけない構造が残っている。 | D11: 小（監視の穴） | E11: 人 | F11: 未着手 | G11: 任意
A12: 8 | B12: 型ルール・投稿枠の効果検証を 09-17 → 09-23 へ延期した（本日実施） | C12: 評価対象コホート 09-10〜09-15 のうち views>0 は 6ch 合計 1 本のみ。09-09〜09-12 の公開停止に加え、views は公開から約 2 日遅れて入る。09-17 では n が揃わず評価できない。 | D12: —（判断の質を守る） | E12: 指揮者 | F12: 適用済 | G12: 2026-09-16
A13: 9 | B13: 維持率 70%以上帯のペナルティを根拠にした施策をこれ以上積まない（本日実施） | C13: 09-15 の「70%以上は登録/千 0.294 で最下位」は、同一条件の再集計で 0.471 となり再現しなかった。頂点が 40-50% 帯であることのみ再現。retention_target_band(40-50) は据え置き、単調な主張は取り下げた。 | D13: —（誤った施策の予防） | E13: 指揮者 | F13: 適用済 | G13: 2026-09-16
A14: 10 | B14: 改善リソースは引き続き高評価率に振る | C14: 200再生以上の四分位で登録/千再生が単調に増える（Q1 0.273 → Q2 0.431 → Q3 0.510 → Q4 0.945・Q4/Q1 3.46倍）。6 回目の再現。コンフィグに記録した 3.40倍 は四分位の切り方が僅かに違うだけで同じ事実。維持率・再生数にはこの単調性が無い。 | D14: 大（唯一の単調な説明変数） | E14: 指揮者 | F14: 継続 | G14: 常時

Sheet トレンド
A1: 公開本数の推移と analytics 同期の欠測
A2: 出典: data/video_publish.db（公開実績）と data/analytics/analytics.db の date 列（同期実績）。2026-09-09〜09-12 は公開と同期が同時に止まっている。
A4: 日付 | B4: 公開本数 | C4: analytics 同期 | D4: daily-science | E4: scp-lab | F4: yokai-watch | G4: company-facts | H4: 2ch-matome | I4: pokemon-lab | J4: その他ch | K4: 備考
A5: 2026-09-03 | B5: 12 | C5: ○ | D5: 1 | E5: 2 | F5: 1 | G5: 1 | H5: 1 | I5: 1 | J5: =IFERROR(B5-SUM(D5:I5),0) -> 5
A6: 2026-09-04 | B6: 25 | C6: ○ | D6: 3 | E6: 2 | F6: 3 | G6: 3 | H6: 3 | I6: 3 | J6: =IFERROR(B6-SUM(D6:I6),0) -> 8
A7: 2026-09-05 | B7: 33 | C7: ○ | D7: 3 | E7: 4 | F7: 3 | G7: 3 | H7: 3 | I7: 3 | J7: =IFERROR(B7-SUM(D7:I7),0) -> 14
A8: 2026-09-06 | B8: 30 | C8: ○ | D8: 3 | E8: 3 | F8: 3 | G8: 3 | H8: 3 | I8: 3 | J8: =IFERROR(B8-SUM(D8:I8),0) -> 12
A9: 2026-09-07 | B9: 27 | C9: ○ | D9: 3 | E9: 3 | F9: 2 | G9: 3 | H9: 3 | I9: 4 | J9: =IFERROR(B9-SUM(D9:I9),0) -> 9
A10: 2026-09-08 | B10: 21 | C10: ○ | D10: 2 | E10: 3 | F10: 3 | G10: 2 | H10: 2 | I10: 2 | J10: =IFERROR(B10-SUM(D10:I10),0) -> 7
A11: 2026-09-09 | B11: 2 | C11: × | D11: 1 | E11: 0 | F11: 0 | G11: 1 | H11: 0 | I11: 0 | J11: =IFERROR(B11-SUM(D11:I11),0) -> 0 | K11: 29 回発火して 2 本のみ公開。この日はトークン失効ログが 0 件で、原因は特定できていない（clip 系のエンジン失敗のみ確認）
A12: 2026-09-10 | B12: 2 | C12: × | D12: 0 | E12: 0 | F12: 0 | G12: 0 | H12: 1 | I12: 1 | J12: =IFERROR(B12-SUM(D12:I12),0) -> 0 | K12: OAuth 失効で公開不能。autopilot は 31/31/28 回発火しており生成は動いていた（失効スキップ 39/24/21 件）
A13: 2026-09-11 | B13: 0 | C13: × | D13: 0 | E13: 0 | F13: 0 | G13: 0 | H13: 0 | I13: 0 | J13: =IFERROR(B13-SUM(D13:I13),0) -> 0 | K13: OAuth 失効で公開不能。autopilot は 31/31/28 回発火しており生成は動いていた（失効スキップ 39/24/21 件）
A14: 2026-09-12 | B14: 0 | C14: × | D14: 0 | E14: 0 | F14: 0 | G14: 0 | H14: 0 | I14: 0 | J14: =IFERROR(B14-SUM(D14:I14),0) -> 0 | K14: OAuth 失効で公開不能。autopilot は 31/31/28 回発火しており生成は動いていた（失効スキップ 39/24/21 件）
A15: 2026-09-13 | B15: 9 | C15: ○ | D15: 2 | E15: 2 | F15: 1 | G15: 3 | H15: 0 | I15: 0 | J15: =IFERROR(B15-SUM(D15:I15),0) -> 1 | K15: 5ch 再認可で復帰（8ch は失効のまま）
A16: 2026-09-14 | B16: 17 | C16: ○ | D16: 4 | E16: 4 | F16: 4 | G16: 4 | H16: 0 | I16: 0 | J16: =IFERROR(B16-SUM(D16:I16),0) -> 1 | K16: 5ch 再認可で復帰（8ch は失効のまま）
A17: 2026-09-15 | B17: 12 | C17: ○ | D17: 2 | E17: 2 | F17: 3 | G17: 4 | H17: 0 | I17: 0 | J17: =IFERROR(B17-SUM(D17:I17),0) -> 1 | K17: 5ch 再認可で復帰（8ch は失効のまま）
A18: 2026-09-16 | B18: 1 | C18: × | D18: 1 | E18: 0 | F18: 0 | G18: 0 | H18: 0 | I18: 0 | J18: =IFERROR(B18-SUM(D18:I18),0) -> 0 | K18: 本日。07:30 に daily-science が公開済み（cTHPSuJr0nA）。video_publish.db は当日分を未記録のため backend.log から補った。進行中の値。
A19: 合計 | B19: =SUM(B5:B18) -> 191 | D19: =SUM(D5:D18) -> 25 | E19: =SUM(E5:E18) -> 25 | F19: =SUM(F5:F18) -> 23 | G19: =SUM(G5:G18) -> 27 | H19: =SUM(H5:H18) -> 16 | I19: =SUM(I5:I18) -> 17 | J19: =SUM(J5:J18) -> 58
A21: 停止によって失われた公開機会の見積り
A23: 項目 | B23: 値 | C23: 根拠
A24: 停止前 4日間（09-05〜09-08）の公開本数 | B24: =SUM(B7:B10) -> 111 | C24: 09-05 33本 / 09-06 30本 / 09-07 27本 / 09-08 21本
A25: 停止前の 1日あたり公開本数 | B25: =B24/4 -> 27.75 | C25: 上記 ÷ 4日
A26: 停止 4日間（09-09〜09-12）の実績 | B26: =SUM(B11:B14) -> 4 | C26: 09-09 2 / 09-10 2 / 09-11 0 / 09-12 0
A27: 失われた公開本数 | B27: =MAX(0,B25*4-B26) -> 107 | C27: 停止前ペースとの差
A28: 平均再生数（全期間・6ch） | B28: =IFERROR(チャンネル別詳細!D11,0) -> 939.17349 | C28: チャンネル別詳細の合計行
A29: 登録/千再生（直近14日・6ch） | B29: =IFERROR(チャンネル別詳細!J11,0) -> 0.68516155 | C29: チャンネル別詳細の合計行
A30: 失われた登録者の見積り（人） | B30: =B27*B28*B29/1000 -> 68.852955 | C30: 失われた本数 × 平均再生 × 登録/千 ÷ 1000。粗い外挿であり実測ではない
A33: OAuth トークンの寿命（scripts/oauth_health_check.py と同じ集計）
A34: 同意画面が「テスト」公開ステータスのままだと、リフレッシュトークンは付与から 7 日で失効する。失効済み 6ch の最終リフレッシュは 7.5〜9.5 日前に固まっており、この仮説と整合する。
A36: channel_id | B36: チャンネル名 | C36: 最終リフレッシュ成功 | D36: 経過日 | E36: 状態
A37: daily-science | B37: リコとマコトのゆっくり日常科学 | C37: 2026-09-16 06:49 | D37: 0.1 | E37: 正常
A38: yokai-watch | B38: ゆっくり妖怪ラボ | C38: 2026-09-15 22:30 | D38: 0.5 | E38: 正常
A39: socio-rx | B39: 社会学の処方箋 | C39: 2026-09-15 22:30 | D39: 0.5 | E39: 正常
A40: scp-lab | B40: 異常存在SCPゆっくり解説ラボ | C40: 2026-09-15 22:30 | D40: 0.5 | E40: 正常
A41: company-facts | B41: 企業のホンネ | C41: 2026-09-15 22:30 | D41: 0.5 | E41: 正常
A42: 2ch-matome | B42: ゆっくり2chスレまとめ劇場 | C42: 2026-09-15 22:30 | D42: 0.5 | E42: 正常
A43: pokemon-lab | B43: ゆっくりポケラボ | C43: 2026-09-10 07:43 | D43: 6.1 | E43: まもなく失効
A44: clip-lab | B44: 切り抜きLab | C44: 2026-09-08 23:00 | D44: 7.5 | E44: 失効（要再認可）
A45: clip-kaneko | B45: 金子みゆ 切り抜きチャンネル | C45: 2026-09-08 23:00 | D45: 7.5 | E45: 失効（要再認可）
A46: clip-fukada | B46: 深田えいみ 切り抜きチャンネル | C46: 2026-09-08 23:00 | D46: 7.5 | E46: 失効（要再認可）
...
