Workbook

Sheet サマリー
A1: YouTube Factory 分析サマリー 2026-09-01
A2: 対象: moviepy系6ch（clip-lab=凍結中 / akashic-librarian=OAuth未連携 のためスキップ）。至上目標はチャンネル登録者数の増加。
A4: ■ 本日の結論
A5: ・登録者増のボトルネックは再生数ではなく「登録転換」。最も再生を集める 2ch-matome が最も登録に繋がっていない。
A6: ・登録転換を最も強く説明するのは高評価率。n=322 の4分位で 0.17→0.32→0.53→1.07（登録/1000再生）と単調増加し、最下位群の6.3倍。
A7: ・一方 終盤維持率(90-100%)は登録と無相関（0.41 / 0.26 / 0.42 / 0.30）。「最後まで見せれば登録される」は本データでは否定された。
A8: ・にもかかわらず 08-29〜31 の実台本32本では 高評価CTA 50% / 登録CTA 38% / 両方 19% しかなく、62%のショートが登録を一度も求めていなかった。
A9: ・company-facts は 高評価0/4・登録0/4 でCTAが皆無。yokai-watch は設定が存在しない「8行目」を指しており高評価CTAの指示が空振りしていた。
A10: ・対策として pipeline/cta_enforcer.py を新設し、最終行に「高評価→登録」を決定論的に保証。あわせて設定4件を修正した。
A12: ■ チャンネル別サマリー（集計は動画別シートを参照）
A13: channel_id | B13: 集計本数 | C13: 視聴回数 | D13: 高評価率 | E13: 登録者増 | F13: 登録/1000再生 | G13: 評価 | H13: 最優先の打ち手
A14: daily-science | B14: =COUNTIFS(動画別パフォーマンス!$A:$A,A14,動画別パフォーマンス!$M:$M,"○") -> 117 | C14: =SUMIFS(動画別パフォーマンス!$D:$D,動画別パフォーマンス!$A:$A,A14,動画別パフォーマンス!$M:$M,"○") -> 110646 | D14: =IF(C14=0,0,SUMIFS(動画別パフォーマンス!$E:$E,動画別パフォーマンス!$A:$A,A14,動画別パフォーマンス!$M:$M,"○")/C14) -> 0.0045731432 | E14: =SUMIFS(動画別パフォーマンス!$G:$G,動画別パフォーマンス!$A:$A,A14,動画別パフォーマンス!$M:$M,"○") -> 41 | F14: =IF(C14=0,0,E14/C14*1000) -> 0.37055113 | G14: =IF(F14>=0.7,"良好",IF(F14>=0.35,"要改善","危険")) -> 要改善 | H14: 高評価率は高いが登録CTAが実台本で0/4。cta_enforcer の効果が最も出るはず。
A15: scp-lab | B15: =COUNTIFS(動画別パフォーマンス!$A:$A,A15,動画別パフォーマンス!$M:$M,"○") -> 99 | C15: =SUMIFS(動画別パフォーマンス!$D:$D,動画別パフォーマンス!$A:$A,A15,動画別パフォーマンス!$M:$M,"○") -> 86345 | D15: =IF(C15=0,0,SUMIFS(動画別パフォーマンス!$E:$E,動画別パフォーマンス!$A:$A,A15,動画別パフォーマンス!$M:$M,"○")/C15) -> 0.0045978343 | E15: =SUMIFS(動画別パフォーマンス!$G:$G,動画別パフォーマンス!$A:$A,A15,動画別パフォーマンス!$M:$M,"○") -> 66 | F15: =IF(C15=0,0,E15/C15*1000) -> 0.76437547 | G15: =IF(F15>=0.7,"良好",IF(F15>=0.35,"要改善","危険")) -> 良好 | H15: 最良。高評価率0.46%・登録0.76を他chの基準にする。SCP-173系の反復は登録1.23と最も効いており、続投してよい。
A16: 2ch-matome | B16: =COUNTIFS(動画別パフォーマンス!$A:$A,A16,動画別パフォーマンス!$M:$M,"○") -> 30 | C16: =SUMIFS(動画別パフォーマンス!$D:$D,動画別パフォーマンス!$A:$A,A16,動画別パフォーマンス!$M:$M,"○") -> 32368 | D16: =IF(C16=0,0,SUMIFS(動画別パフォーマンス!$E:$E,動画別パフォーマンス!$A:$A,A16,動画別パフォーマンス!$M:$M,"○")/C16) -> 0.0025333663 | E16: =SUMIFS(動画別パフォーマンス!$G:$G,動画別パフォーマンス!$A:$A,A16,動画別パフォーマンス!$M:$M,"○") -> 5 | F16: =IF(C16=0,0,E16/C16*1000) -> 0.15447355 | G16: =IF(F16>=0.7,"良好",IF(F16>=0.35,"要改善","危険")) -> 危険 | H16: 最大の課題。再生は最多だが登録は最低。高評価率0.25%をまず0.4%へ。参加型CTAが高評価CTAを押しのけている。
A17: pokemon-lab | B17: =COUNTIFS(動画別パフォーマンス!$A:$A,A17,動画別パフォーマンス!$M:$M,"○") -> 30 | C17: =SUMIFS(動画別パフォーマンス!$D:$D,動画別パフォーマンス!$A:$A,A17,動画別パフォーマンス!$M:$M,"○") -> 40101 | D17: =IF(C17=0,0,SUMIFS(動画別パフォーマンス!$E:$E,動画別パフォーマンス!$A:$A,A17,動画別パフォーマンス!$M:$M,"○")/C17) -> 0.002917633 | E17: =SUMIFS(動画別パフォーマンス!$G:$G,動画別パフォーマンス!$A:$A,A17,動画別パフォーマンス!$M:$M,"○") -> 11 | F17: =IF(C17=0,0,E17/C17*1000) -> 0.27430737 | G17: =IF(F17>=0.7,"良好",IF(F17>=0.35,"要改善","危険")) -> 危険 | H17: 高評価率0.29%が低い。『え、マジで？』の驚き設計を3行目の数字比較に集中させる。
A18: yokai-watch | B18: =COUNTIFS(動画別パフォーマンス!$A:$A,A18,動画別パフォーマンス!$M:$M,"○") -> 30 | C18: =SUMIFS(動画別パフォーマンス!$D:$D,動画別パフォーマンス!$A:$A,A18,動画別パフォーマンス!$M:$M,"○") -> 39077 | D18: =IF(C18=0,0,SUMIFS(動画別パフォーマンス!$E:$E,動画別パフォーマンス!$A:$A,A18,動画別パフォーマンス!$M:$M,"○")/C18) -> 0.0037106226 | E18: =SUMIFS(動画別パフォーマンス!$G:$G,動画別パフォーマンス!$A:$A,A18,動画別パフォーマンス!$M:$M,"○") -> 11 | F18: =IF(C18=0,0,E18/C18*1000) -> 0.28149551 | G18: =IF(F18>=0.7,"良好",IF(F18>=0.35,"要改善","危険")) -> 危険 | H18: 『8行目』誤記で高評価CTAが空振りしていた。修正済みのため次サイクルで効果を測る。
A19: company-facts | B19: =COUNTIFS(動画別パフォーマンス!$A:$A,A19,動画別パフォーマンス!$M:$M,"○") -> 0 | C19: =SUMIFS(動画別パフォーマンス!$D:$D,動画別パフォーマンス!$A:$A,A19,動画別パフォーマンス!$M:$M,"○") -> 0 | D19: =IF(C19=0,0,SUMIFS(動画別パフォーマンス!$E:$E,動画別パフォーマンス!$A:$A,A19,動画別パフォーマンス!$M:$M,"○")/C19) -> 0 | E19: =SUMIFS(動画別パフォーマンス!$G:$G,動画別パフォーマンス!$A:$A,A19,動画別パフォーマンス!$M:$M,"○") -> 0 | F19: =IF(C19=0,0,E19/C19*1000) -> 0 | G19: =IF(F19>=0.7,"良好",IF(F19>=0.35,"要改善","危険")) -> 危険 | H19: CTAが皆無（高評価0/4・登録0/4）。加えて video_metrics に取り込まれておらず実績が測れていない。取り込み経路の確認が必要。
A20: 合計 / 加重平均 | B20: =SUM(B14:B19) -> 306 | C20: =SUM(C14:C19) -> 308537 | D20: =IF(C20=0,0,SUM(E14:E19)*0+SUMPRODUCT(C14:C19,D14:D19)/C20) -> 0.0040416546 | E20: =SUM(E14:E19) -> 134 | F20: =IF(C20=0,0,E20/C20*1000) -> 0.43430772
A22: ■ 高評価率と登録転換の関係（本日の中核的発見・n=322）
A23: 高評価率の帯 | B23: 本数 | C23: 平均視聴回数 | D23: 登録/1000再生 | E23: 最下位群比
A24: 0-0.2% | B24: 72 | C24: 821 | D24: 0.17 | E24: =IF($D$24=0,0,D24/$D$24) -> 1
A25: 0.2-0.4% | B25: 102 | C25: 1101 | D25: 0.32 | E25: =IF($D$24=0,0,D25/$D$24) -> 1.8823529
A26: 0.4-0.8% | B26: 119 | C26: 1007 | D26: 0.53 | E26: =IF($D$24=0,0,D26/$D$24) -> 3.1176471
A27: 0.8%以上 | B27: 29 | C27: 804 | D27: 1.07 | E27: =IF($D$24=0,0,D27/$D$24) -> 6.2941176
A29: ■ 終盤維持率と登録転換（無相関・改善対象から外す根拠）
A30: 終盤維持率(90-100%) | B30: 本数 | C30: 平均視聴回数 | D30: 登録/1000再生
A31: 15%未満 | B31: 76 | C31: 1047 | D31: 0.41
A32: 15-25% | B32: 43 | C32: 1157 | D32: 0.26
A33: 25-40% | B33: 28 | C33: 1191 | D33: 0.42
A34: 40%以上 | B34: 15 | C34: 1327 | D34: 0.3
A35: → 単調性が無く、最上位帯がむしろ低い。登録の打ち手として終盤維持率は追わない。

Sheet チャンネル別詳細
A1: チャンネル別詳細
A2: 維持率カーブは retention_curve の全曲線をチャンネル平均したもの（100%超は再視聴・ループを含むYouTube仕様）。
A4: ■ 08月の登録者純増（channel_metrics・APIの反映遅延により08-28まで）
A5: channel_id | B5: 視聴回数 | C5: 登録増 | D5: 登録減 | E5: 純増 | F5: 登録/1000再生
A6: 2ch-matome | B6: 32370 | C6: 9 | D6: 2 | E6: =C6-D6 -> 7 | F6: =IF(B6=0,0,E6/B6*1000) -> 0.21624961
A7: daily-science | B7: 39413 | C7: 22 | D7: 9 | E7: =C7-D7 -> 13 | F7: =IF(B7=0,0,E7/B7*1000) -> 0.32984041
A8: fake-paper | B8: 4185 | C8: 0 | D8: 0 | E8: =C8-D8 -> 0 | F8: =IF(B8=0,0,E8/B8*1000) -> 0
A9: pokemon-lab | B9: 41459 | C9: 15 | D9: 4 | E9: =C9-D9 -> 11 | F9: =IF(B9=0,0,E9/B9*1000) -> 0.26532237
A10: scp-lab | B10: 36211 | C10: 34 | D10: 6 | E10: =C10-D10 -> 28 | F10: =IF(B10=0,0,E10/B10*1000) -> 0.7732457
A11: yokai-watch | B11: 39700 | C11: 13 | D11: 3 | E11: =C11-D11 -> 10 | F11: =IF(B11=0,0,E11/B11*1000) -> 0.25188917
A13: ■ 平均維持率カーブ（%）
A14: channel_id | B14: 本数 | C14: 0% | D14: 10% | E14: 20% | F14: 30% | G14: 40% | H14: 50% | I14: 60% | J14: 70% | K14: 80% | L14: 90% | M14: 100%
A15: 2ch-matome | B15: 16 | C15: 1.1035812 | D15: 1.0275761 | E15: 0.742425 | F15: 0.54421625 | G15: 0.43297847 | H15: 0.35383375 | I15: 0.29654 | J15: 0.25119375 | K15: 0.18640341 | L15: 0.13441812 | M15: 0.113455
A16: daily-science | B16: 66 | C16: 1.2539053 | D16: 1.1815674 | E16: 0.88296045 | F16: 0.6724553 | G16: 0.5728564 | H16: 0.50930864 | I16: 0.45950455 | J16: 0.42434121 | K16: 0.36879174 | L16: 0.29279348 | M16: 0.26726939
A17: fake-paper | B17: 5 | C17: 1.09322 | D17: 0.98616909 | E17: 0.49965 | F17: 0.330826 | G17: 0.25016667 | H17: 0.20572 | I17: 0.168698 | J17: 0.14599 | K17: 0.12855455 | L17: 0.109654 | M17: 0.099692
A18: pokemon-lab | B18: 31 | C18: 1.1989653 | D18: 1.1002971 | E18: 0.84712742 | F18: 0.65657613 | G18: 0.55984122 | H18: 0.49982871 | I18: 0.470981 | J18: 0.436844 | K18: 0.37259545 | L18: 0.261086 | M18: 0.2248
A19: scp-lab | B19: 32 | C19: 1.1594398 | D19: 1.0875665 | E19: 0.82496406 | F19: 0.60771562 | G19: 0.49714375 | H19: 0.44041906 | I19: 0.40037875 | J19: 0.3711275 | K19: 0.33063352 | L19: 0.22954406 | M19: 0.18004687
A20: yokai-watch | B20: 32 | C20: 1.1771414 | D20: 1.0789946 | E20: 0.78899594 | F20: 0.58693781 | G20: 0.47719965 | H20: 0.41644594 | I20: 0.37231969 | J20: 0.33529906 | K20: 0.29828551 | L20: 0.23409806 | M20: 0.19905871
A22: → 全チャンネルで 10%→30% の区間が最大の崖。ただし終盤維持率は登録と無相関のため、ここの改善は視聴時間には効くが登録者数には効かない（サマリー参照）。

Sheet 動画別パフォーマンス
A1: 動画別パフォーマンス（各動画の最新スナップショット）
A2: 出典: data/analytics/analytics.db video_metrics / retention_curve。視聴回数200未満は統計ノイズが大きいため集計から除外している（除外行はグレー表示）。
A4: channel_id | B4: 公開日 | C4: タイトル | D4: 視聴回数 | E4: 高評価 | F4: 高評価率 | G4: 登録者増 | H4: 登録/1000再生 | I4: インプレッション | J4: CTR | K4: 平均視聴率 | L4: 終盤維持率(90-100%) | M4: 集計対象
A5: 2ch-matome | B5: 2026-08-09 | C5: 30秒スレまとめ：残業代はやる気で払う#上司「残業代はやる気で払う」発言から、なぜか全員消えた職場の末路 #shorts #ゆっくり解説 | D5: 1360 | E5: 3 | F5: =IF(D5=0,0,E5/D5) -> 0.0022058824 | G5: 0 | H5: =IF(D5=0,0,G5/D5*1000) -> 0 | I5: 46 | J5: 0.10869565 | K5: 0.4507 | L5: 0.11222 | M5: =IF(D5>=200,"○","-") -> ○
A6: 2ch-matome | B6: 2026-08-13 | C6: ワイの今日の昼飯を当てるスレw【ショート】 | D6: 1438 | E6: 3 | F6: =IF(D6=0,0,E6/D6) -> 0.0020862309 | G6: 0 | H6: =IF(D6=0,0,G6/D6*1000) -> 0 | I6: 52 | J6: 0.019230769 | K6: 0.6644 | L6: 0.237195 | M6: =IF(D6>=200,"○","-") -> ○
A7: 2ch-matome | B7: 2026-08-13 | C7: コンビニで一番いらん商品あげてけ【ショート】 | D7: 1086 | E7: 1 | F7: =IF(D7=0,0,E7/D7) -> 0.00092081031 | G7: 0 | H7: =IF(D7=0,0,G7/D7*1000) -> 0 | I7: 36 | J7: 0.027777778 | K7: 1.2551 | M7: =IF(D7>=200,"○","-") -> ○
A8: 2ch-matome | B8: 2026-08-14 | C8: なんかPCの画面チカチカするんやが【ショート】 | D8: 1305 | E8: 4 | F8: =IF(D8=0,0,E8/D8) -> 0.0030651341 | G8: 2 | H8: =IF(D8=0,0,G8/D8*1000) -> 1.532567 | I8: 75 | J8: 0.026666667 | K8: 0.5116 | L8: 0.10096 | M8: =IF(D8>=200,"○","-") -> ○
A9: 2ch-matome | B9: 2026-08-14 | C9: 彼女の部屋でヤバい物あげてけw【ショート】 | D9: 1366 | E9: 3 | F9: =IF(D9=0,0,E9/D9) -> 0.0021961933 | G9: 1 | H9: =IF(D9=0,0,G9/D9*1000) -> 0.73206442 | I9: 33 | J9: 0 | K9: 0.4988 | L9: 0.085165 | M9: =IF(D9>=200,"○","-") -> ○
A10: 2ch-matome | B10: 2026-08-15 | C10: ワイ、彼女いない歴＝年齢やけど質問ある？【ショート】 | D10: 1655 | E10: 4 | F10: =IF(D10=0,0,E10/D10) -> 0.0024169184 | G10: 0 | H10: =IF(D10=0,0,G10/D10*1000) -> 0 | I10: 35 | J10: 0.085714286 | K10: 0.6419 | L10: 0.192105 | M10: =IF(D10>=200,"○","-") -> ○
A11: 2ch-matome | B11: 2026-08-15 | C11: ワイのキーボードの変な癖あげてけw【ショート】 | D11: 1190 | E11: 0 | F11: =IF(D11=0,0,E11/D11) -> 0 | G11: 0 | H11: =IF(D11=0,0,G11/D11*1000) -> 0 | I11: 25 | J11: 0 | K11: 0.5127 | M11: =IF(D11>=200,"○","-") -> ○
A12: 2ch-matome | B12: 2026-08-16 | C12: なんかスマホの充電だけ遅いんやが【ショート】 | D12: 1350 | E12: 1 | F12: =IF(D12=0,0,E12/D12) -> 0.00074074074 | G12: 0 | H12: =IF(D12=0,0,G12/D12*1000) -> 0 | I12: 30 | J12: 0 | K12: 0.7217 | L12: 0.33558 | M12: =IF(D12>=200,"○","-") -> ○
A13: 2ch-matome | B13: 2026-08-17 | C13: 後輩「敬語って課金制ですよね？」→翌朝、全員が黙った #shorts #2ch #スカッと | D13: 1353 | E13: 4 | F13: =IF(D13=0,0,E13/D13) -> 0.0029563932 | G13: 0 | H13: =IF(D13=0,0,G13/D13*1000) -> 0 | I13: 32 | J13: 0 | K13: 0.5715 | L13: 0.226515 | M13: =IF(D13>=200,"○","-") -> ○
A14: 2ch-matome | B14: 2026-08-17 | C14: 実際には存在しないけどありそうな県名あげてけ【ショート】 | D14: 1161 | E14: 3 | F14: =IF(D14=0,0,E14/D14) -> 0.0025839793 | G14: 0 | H14: =IF(D14=0,0,G14/D14*1000) -> 0 | I14: 27 | J14: 0 | K14: 1.096 | M14: =IF(D14>=200,"○","-") -> ○
A15: 2ch-matome | B15: 2026-08-17 | C15: 絶対に二度見される部屋着あげてけw【ショート】 | D15: 1236 | E15: 6 | F15: =IF(D15=0,0,E15/D15) -> 0.0048543689 | G15: 0 | H15: =IF(D15=0,0,G15/D15*1000) -> 0 | I15: 23 | J15: 0 | K15: 0.8136 | M15: =IF(D15>=200,"○","-") -> ○
A16: 2ch-matome | B16: 2026-08-17 | C16: ワイ、AIに変な質問する係やけど質問ある？w【ショート】 | D16: 1 | E16: 0 | F16: =IF(D16=0,0,E16/D16) -> 0 | G16: 0 | H16: =IF(D16=0,0,G16/D16*1000) -> 0 | I16: 33 | J16: 0 | K16: 0.808 | M16: =IF(D16>=200,"○","-") -> -
A17: 2ch-matome | B17: 2026-08-17 | C17: 飲み会で絶対見られたくない通知あげてけw【ショート】 | D17: 2 | E17: 0 | F17: =IF(D17=0,0,E17/D17) -> 0 | G17: 0 | H17: =IF(D17=0,0,G17/D17*1000) -> 0 | I17: 24 | J17: 0 | K17: 0.3383 | M17: =IF(D17>=200,"○","-") -> -
A18: 2ch-matome | B18: 2026-08-18 | C18: 存在しないゲームの迷惑機能あげてけw【ショート】 | D18: 1144 | E18: 2 | F18: =IF(D18=0,0,E18/D18) -> 0.0017482517 | G18: 0 | H18: =IF(D18=0,0,G18/D18*1000) -> 0 | I18: 22 | J18: 0 | K18: 0.514 | M18: =IF(D18>=200,"○","-") -> ○
A19: 2ch-matome | B19: 2026-08-18 | C19: なんか靴下だけ消えるんやがw【ショート】 | D19: 702 | E19: 1 | F19: =IF(D19=0,0,E19/D19) -> 0.0014245014 | G19: 0 | H19: =IF(D19=0,0,G19/D19*1000) -> 0 | I19: 33 | J19: 0.03030303 | K19: 0.5542 | M19: =IF(D19>=200,"○","-") -> ○
A20: 2ch-matome | B20: 2026-08-19 | C20: PCパーツ到着時、なぜ箱だけ先に届くのか？【ショート】 | D20: 1811 | E20: 4 | F20: =IF(D20=0,0,E20/D20) -> 0.0022087245 | G20: 0 | H20: =IF(D20=0,0,G20/D20*1000) -> 0 | I20: 32 | J20: 0.28125 | K20: 0.4193 | L20: 0.070905 | M20: =IF(D20>=200,"○","-") -> ○
A21: 2ch-matome | B21: 2026-08-19 | C21: なぜケンタッキー月見は3秒で秋の給料日になるのか、食べた感想あげてけw【ショート】 | D21: 249 | E21: 0 | F21: =IF(D21=0,0,E21/D21) -> 0 | G21: 0 | H21: =IF(D21=0,0,G21/D21*1000) -> 0 | I21: 139 | J21: 0 | K21: 0.3493 | M21: =IF(D21>=200,"○","-") -> ○
A22: 2ch-matome | B22: 2026-08-20 | C22: ちいかわチョコサプ、なぜ中身が攻めすぎなのか？3秒予想してみたら草【ショート】 | D22: 820 | E22: 1 | F22: =IF(D22=0,0,E22/D22) -> 0.0012195122 | G22: 1 | H22: =IF(D22=0,0,G22/D22*1000) -> 1.2195122 | I22: 27 | J22: 0 | K22: 0.3193 | M22: =IF(D22>=200,"○","-") -> ○
A23: 2ch-matome | B23: 2026-08-20 | C23: ワイ、アジア大会珍プレー歴0年やけど質問ある？w🤣【ショート】 | D23: 587 | E23: 1 | F23: =IF(D23=0,0,E23/D23) -> 0.0017035775 | G23: 0 | H23: =IF(D23=0,0,G23/D23*1000) -> 0 | I23: 53 | J23: 0.018867925 | K23: 0.2448 | M23: =IF(D23>=200,"○","-") -> ○
A24: 2ch-matome | B24: 2026-08-21 | C24: 3秒で考えろ！この戦闘機の名前が親戚回避型な理由とは？【ショート】 | D24: 967 | E24: 5 | F24: =IF(D24=0,0,E24/D24) -> 0.0051706308 | G24: 0 | H24: =IF(D24=0,0,G24/D24*1000) -> 0 | I24: 26 | J24: 0 | K24: 0.3263 | L24: 0.06039 | M24: =IF(D24>=200,"○","-") -> ○
A25: 2ch-matome | B25: 2026-08-21 | C25: ワイ、サーモス歴3年やけど質問ある？w😏【ショート】 | D25: 950 | E25: 3 | F25: =IF(D25=0,0,E25/D25) -> 0.0031578947 | G25: 0 | H25: =IF(D25=0,0,G25/D25*1000) -> 0 | I25: 32 | J25: 0 | K25: 0.3644 | M25: =IF(D25>=200,"○","-") -> ○
A26: 2ch-matome | B26: 2026-08-21 | C26: なぜ熱闘甲子園の夜だけ空気が変わる？お前らの夏の思い出5つ聞かせろ【ショート】 | D26: 967 | E26: 5 | F26: =IF(D26=0,0,E26/D26) -> 0.0051706308 | G26: 0 | H26: =IF(D26=0,0,G26/D26*1000) -> 0 | I26: 51 | J26: 0 | K26: 0.3015 | L26: 0.09793 | M26: =IF(D26>=200,"○","-") -> ○
A27: 2ch-matome | B27: 2026-08-22 | C27: なぜ3秒でバレる？お前らをブラックラグーンで例えた結果【ショート】 | D27: 1088 | E27: 1 | F27: =IF(D27=0,0,E27/D27) -> 0.00091911765 | G27: 0 | H27: =IF(D27=0,0,G27/D27*1000) -> 0 | I27: 249 | J27: 0.0040160643 | K27: 0.2712 | L27: 0.093515 | M27: =IF(D27>=200,"○","-") -> ○
A28: 2ch-matome | B28: 2026-08-23 | C28: ワイ、GTA6妄想歴6年やけど質問ある？w💦【ショート】 | D28: 1088 | E28: 0 | F28: =IF(D28=0,0,E28/D28) -> 0 | G28: 0 | H28: =IF(D28=0,0,G28/D28*1000) -> 0 | I28: 31 | J28: 0 | K28: 0.231 | L28: 0.02785 | M28: =IF(D28>=200,"○","-") -> ○
A29: 2ch-matome | B29: 2026-08-24 | C29: 味の素3粒、実は何に使うのか？意外すぎる活用法をあげてけｗ【ショート】 | D29: 1153 | E29: 7 | F29: =IF(D29=0,0,E29/D29) -> 0.0060711188 | G29: 0 | H29: =IF(D29=0,0,G29/D29*1000) -> 0 | I29: 54 | J29: 0 | K29: 0.2663 | L29: 0.03911 | M29: =IF(D29>=200,"○","-") -> ○
A30: 2ch-matome | B30: 2026-08-25 | C30: 🤯ワイ、友達の家でヤバい物を3個見たんやがw🤯【ショート】 | D30: 855 | E30: 2 | F30: =IF(D30=0,0,E30/D30) -> 0.0023391813 | G30: 0 | H30: =IF(D30=0,0,G30/D30*1000) -> 0 | I30: 20 | J30: 0 | K30: 0.3913 | M30: =IF(D30>=200,"○","-") -> ○
A31: 2ch-matome | B31: 2026-08-26 | C31: 実は迷子続出？ドラゴンボールパークで何が起きたのか【ショート】 | D31: 961 | E31: 5 | F31: =IF(D31=0,0,E31/D31) -> 0.0052029136 | G31: 0 | H31: =IF(D31=0,0,G31/D31*1000) -> 0 | I31: 51 | J31: 0.019607843 | K31: 0.3465 | M31: =IF(D31>=200,"○","-") -> ○
A32: 2ch-matome | B32: 2026-08-27 | C32: 彼女の家で開けたらアカン引き出し開けたんやが #shorts #2ch #面白いスレ | D32: 839 | E32: 1 | F32: =IF(D32=0,0,E32/D32) -> 0.0011918951 | G32: 0 | H32: =IF(D32=0,0,G32/D32*1000) -> 0 | I32: 67 | J32: 0 | K32: 0.5066 | L32: 0.175505 | M32: =IF(D32>=200,"○","-") -> ○
A33: 2ch-matome | B33: 2026-08-27 | C33: 🤣ワイ、大谷の昼飯を3秒で当てるスレw🤣【ショート】 | D33: 957 | E33: 3 | F33: =IF(D33=0,0,E33/D33) -> 0.0031347962 | G33: 0 | H33: =IF(D33=0,0,G33/D33*1000) -> 0 | I33: 39 | J33: 0 | K33: 1.4519 | M33: =IF(D33>=200,"○","-") -> ○
A34: 2ch-matome | B34: 2026-08-28 | C34: 💦ワイ、夫が寝た後の秘密3つあげてけw🤣【ショート】 | D34: 878 | E34: 1 | F34: =IF(D34=0,0,E34/D34) -> 0.0011389522 | G34: 0 | H34: =IF(D34=0,0,G34/D34*1000) -> 0 | I34: 15 | J34: 0 | K34: 0.3578 | M34: =IF(D34>=200,"○","-") -> ○
A35: 2ch-matome | B35: 2026-08-28 | C35: 🤣ワイ、落雷を3秒で見たんやが質問ある？w🍑【ショート】 | D35: 926 | E35: 4 | F35: =IF(D35=0,0,E35/D35) -> 0.0043196544 | G35: 0 | H35: =IF(D35=0,0,G35/D35*1000) -> 0 | I35: 20 | J35: 0 | K35: 0.307 | L35: 0.0291 | M35: =IF(D35>=200,"○","-") -> ○
A36: 2ch-matome | B36: 2026-08-29 | C36: なぜPS5 Proに期待する？値段で胃が痛い理由とはw【ショート】 | D36: 926 | E36: 4 | F36: =IF(D36=0,0,E36/D36) -> 0.0043196544 | G36: 1 | H36: =IF(D36=0,0,G36/D36*1000) -> 1.0799136 | I36: 22 | J36: 0.045454545 | K36: 0.3787 | L36: 0.09894 | M36: =IF(D36>=200,"○","-") -> ○
A37: 2ch-matome | B37: 2026-08-30 | C37: 動画作りに7万課金した男、なぜ昼飯が塩むすびになったのか？【ショート】 | D37: 0 | E37: 0 | F37: =IF(D37=0,0,E37/D37) -> 0 | G37: 0 | H37: =IF(D37=0,0,G37/D37*1000) -> 0 | I37: 0 | J37: 0 | K37: 0 | M37: =IF(D37>=200,"○","-") -> -
A38: 2ch-matome | B38: 2026-08-30 | C38: 実は家族に見られた通販履歴…一番言い訳できない理由は？【ショート】 | D38: 0 | E38: 0 | F38: =IF(D38=0,0,E38/D38) -> 0 | G38: 0 | H38: =IF(D38=0,0,G38/D38*1000) -> 0 | I38: 0 | J38: 0 | K38: 0 | M38: =IF(D38>=200,"○","-") -> -
A39: 2ch-matome | B39: 2026-08-31 | C39: なぜPSで一番いらないゲームが生まれるのか？ 博牛【ショート】 | D39: 0 | E39: 0 | F39: =IF(D39=0,0,E39/D39) -> 0 | G39: 0 | H39: =IF(D39=0,0,G39/D39*1000) -> 0 | I39: 0 | J39: 0 | K39: 0 | M39: =IF(D39>=200,"○","-") -> -
A40: daily-science | B40: 2026-05-12 | C40: 【ゆっくり解説】雨の日に落ち込むのは科学的根拠があった！「雨の日に気分が落ち込むのは錯覚じゃなかった！科学で判明した驚きの理由」 | D40: 0 | E40: 0 | F40: =IF(D40=0,0,E40/D40) -> 0 | G40: 0 | H40: =IF(D40=0,0,G40/D40*1000) -> 0 | I40: 0 | J40: 0 | K40: 0 | M40: =IF(D40>=200,"○","-") -> -
A41: daily-science | B41: 2026-05-13 | C41: 【ゆっくり解説】同じ星を見てるのになぜ形が違うの？「【衝撃】星座の形が人によって違う理由が意外すぎた…文化で変わる夜空の見方」 | D41: 0 | E41: 0 | F41: =IF(D41=0,0,E41/D41) -> 0 | G41: 0 | H41: =IF(D41=0,0,G41/D41*1000) -> 0 | I41: 0 | J41: 0 | K41: 0 | M41: =IF(D41>=200,"○","-") -> -
...

Sheet 改善アクション
A1: 改善アクション 2026-09-01
A2: 「実施済」は本日このタスクが実装・反映まで完了したもの。効果は明日以降の実測で検証する。
A4: # | B4: 対象 | C4: 課題（実測） | D4: 対応 | E4: 状態 | F4: 変更ファイル | G4: 検証方法
A5: 1 | B5: 全6ch | C5: ショート最終行の実測で 高評価CTA 50% / 登録CTA 38% / 両方 19%。62%が登録を一度も求めていない。 | D5: cta_enforcer.py を新設し、最終行に「高評価→登録」を決定論的に保証。CTA後のループ誘導句も除去。字数超過時はCTA2文へ畳む。 | E5: 実施済 | F5: backend/pipeline/cta_enforcer.py（新規） | G5: python3 scripts/verify_cta_20260901.py → 両方100%
A6: 2 | B6: 全6ch | C6: cta_enforcer を実レンダリング経路に繋がないと 08-30 の尺ガードと同じ空振りになる。 | D6: video_generator.py の shorts_length_guard 直前に接続（CTA付与後の字数で尺ガードが効く順序）。 | E6: 実施済 | F6: backend/pipeline/video_generator.py | G6: logs/backend.log の「📣 CTA補正」
A7: 3 | B7: 全6ch | C7: scenario_validator の CTA 検査に高評価の語が無く、登録のみ・かつ strict=False で素通りしていた。 | D7: LIKE_PATTERNS を追加し、_check_cta を「高評価+登録の両方」必須に変更（片方欠けで-12、両方欠けで-25）。 | E7: 実施済 | F7: backend/pipeline/scenario_validator.py | G7: backend/tests/test_cta_enforcer.py（36件パス）
A8: 4 | B8: yokai-watch | C8: extra_rules が存在しない「8行目」を指定。structure は6行しかなく、高評価CTAの指示が空振りしていた（実測 高評価1/3）。 | D8: 「8行目」→「6行目」に修正。 | E8: 実施済 | F8: data/channels{,_orchestrator}/yokai-watch.json | G8: grep '8行目' で0件
A9: 5 | B9: company-facts | C9: 唯一 高評価0/4・登録0/4 でCTAが皆無。末尾がプロフィール誘導のみで終わっていた。 | D9: structure 6行目に登録CTAを明示し、cta_fallback を追加。 | E9: 実施済 | F9: data/channels{,_orchestrator}/company-facts.json | G9: verify_cta_20260901.py の company-facts 行
A10: 6 | B10: 全6ch | C10: 設定の根拠が旧値の「2.16倍」のままで、終盤維持率を追うべきという誤った示唆が残っていた。 | D10: 根拠を 6.3倍（n=322・単調）に更新し、「終盤維持率は登録と無相関」という否定的知見を明記。 | E10: 実施済 | F10: data/channels{,_orchestrator}/*.json（6ch） | G10: extra_rules[0] に 'n=322' が入っているか
A11: 7 | B11: 2ch-matome | C11: 再生は最多（14日で24,198）だが登録純増3、登録/1000再生0.12で全ch最低。高評価率も0.25%と最低。 | D11: cta_enforcer により高評価CTAを毎回先頭で保証。参加型CTA（コメント誘導）が高評価CTAを押しのけていた構造を是正。 | E11: 実施済 | F11: cta_enforcer の 2ch-matome 既定句 | G11: 高評価率 0.25%→0.40% を1週間で確認
A12: 8 | B12: company-facts | C12: style=facts_overlay は yukkuri とは別経路を通るため、当初の実装（yukkuri分岐の内側）ではCTA補正が効かなかった。CTAが皆無だったまさにそのチャンネルだけ対象外という、08-30の尺ガードと同じ失敗。 | D12: cta_enforcer の呼び出しを style 分岐より前へ移動し、全スタイル（facts_overlay / monologue / yukkuri）に適用。あわせて画面CTAカード（video_format.facts_overlay.cta）も『他の企業もチェック／プロフィールから見れます』→『高評価とチャンネル登録／毎日1社の実態が届きます』に変更。 | E12: 実施済 | F12: video_generator.py, data/channels{,_orchestrator}/company-facts.json | G12: logs/backend.log の「📣 CTA補正[company-facts]」
A13: 9 | B13: 全6ch | C13: 台本が「睡眠と夢シリーズシリーズ」「裏設定ファイルシリーズシリーズ」と重複を書き、そのまま読み上げられていた。series_lineup の値が既に『〜シリーズ』で終わるのに generator がシリーズ名への言及を指示するため。cta_rotator側の同等修正は12chで無効。 | D13: cta_enforcer で最終行の『シリーズシリーズ』を機械的に解消。 | E13: 実施済 | F13: backend/pipeline/cta_enforcer.py | G13: テスト TestSeriesDedup（57件パス）
A14: 10 | B14: company-facts | C14: video_metrics に1行も取り込まれていない（reach側には24本ある）。実績が測定できていない。 | D14: 取り込み経路の調査が必要。本タスクはサンドボックスから YouTube API を叩けないため未着手。 | E14: 要対応 | F14: （未変更・要調査） | G14: video_metrics に company-facts 行が出現するか
A15: 11 | B15: 全6ch | C15: scenario_validator の CTA 検査は基礎点50に対し減点が最大-25で、閾値60を下回らないため実質的に生成を止めない。 | D15: 無人実行で閾値を上げると生成本数がゼロになる恐れがあるため、今回は閾値を変更しない。強制は決定論的な cta_enforcer 側で担保し、validator はスコア指標に留める。 | E15: 見送り | F15: （変更なし・意図的） | G15: cta_enforcer が実経路で効いていれば validator の厳格化は不要
A16: 12 | B16: daily-science / pokemon-lab | C16: シリーズ番号プレフィックスは ch内統制で登録0.69 vs 0.33（daily-science）と有意に見えるが n=13/11 と薄い。yokai-watch では逆転（0.14 vs 0.31）。 | D16: チャンネル横断で一律に戻すのは根拠不足と判断し、今回は変更しない。A/Bテストの候補として記録のみ。 | E16: 見送り | F16: （変更なし） | G16: n が各30本を超えた時点で再評価

Sheet トレンド
A1: トレンド
A2: 公開時期別の推移と競合比較。時期別は各動画の最新スナップショットを公開日で束ねたもの。
A4: ■ 公開時期別の推移（高評価率の落ち込みと回復）
A5: 公開時期 | B5: 本数 | C5: 平均視聴回数 | D5: 高評価率 | E5: 登録/1000再生
A6: 〜07月 | B6: 133 | D6: 0.00477 | E6: 0.52
A7: 08/01-05 | B7: 34 | D7: 0.00413 | E7: 0.54
A8: 08/06-10 | B8: 30 | D8: 0.00336 | E8: 0.31
A9: 08/11-15 | B9: 26 | D9: 0.0027 | E9: 0.33
A10: 08/16-20 | B10: 26 | D10: 0.00317 | E10: 0.24
A11: 08/21-25 | B11: 30 | D11: 0.00369 | E11: 0.27
A12: 08/26-30 | B12: 32 | D12: 0.00436 | E12: 0.46
A14: → 08/11-15 を底に高評価率が落ち込み、08/26-30 で回復。7月水準（0.477%）にはまだ戻っていない。08-31 に修正された台本破損・尺超過の影響時期と重なる。
A16: ■ CTA遵守率の実測（08-29〜31・ショート最終行）
A17: channel_id | B17: 本数 | C17: 高評価CTA | D17: 登録CTA | E17: 両方
A18: 2ch-matome | B18: 4 | C18: =IF($B18=0,0,3/$B18) -> 0.75 | D18: =IF($B18=0,0,1/$B18) -> 0.25 | E18: =IF($B18=0,0,1/$B18) -> 0.25
A19: company-facts | B19: 4 | C19: =IF($B19=0,0,0/$B19) -> 0 | D19: =IF($B19=0,0,0/$B19) -> 0 | E19: =IF($B19=0,0,0/$B19) -> 0
A20: daily-science | B20: 4 | C20: =IF($B20=0,0,3/$B20) -> 0.75 | D20: =IF($B20=0,0,0/$B20) -> 0 | E20: =IF($B20=0,0,0/$B20) -> 0
A21: pokemon-lab | B21: 4 | C21: =IF($B21=0,0,3/$B21) -> 0.75 | D21: =IF($B21=0,0,1/$B21) -> 0.25 | E21: =IF($B21=0,0,1/$B21) -> 0.25
A22: scp-lab | B22: 7 | C22: =IF($B22=0,0,5/$B22) -> 0.71428571 | D22: =IF($B22=0,0,5/$B22) -> 0.71428571 | E22: =IF($B22=0,0,4/$B22) -> 0.57142857
A23: yokai-watch | B23: 3 | C23: =IF($B23=0,0,1/$B23) -> 0.33333333 | D23: =IF($B23=0,0,0/$B23) -> 0 | E23: =IF($B23=0,0,0/$B23) -> 0
A26: ■ 競合比較（最新スキャン）
A27: 自ch | B27: 競合チャンネル | C27: 登録者数 | D27: 平均視聴回数 | E27: 週間投稿数 | F27: 調査日
A28: 2ch-matome | B28: 2ちゃんねる面白スレまとめ【ゆっくり解説】 | C28: 412000 | D28: 296233 | E28: 15.07 | F28: 2026-08-30
A29: 2ch-matome | B29: 2ch面白いスレまとめイッチーズ | C29: 224000 | D29: 111944 | E29: 3.18 | F29: 2026-08-30
A30: 2ch-matome | B30: 2chの質問ある?スレまとめ【ゆっくり夫】 | C30: 102000 | D30: 4875 | E30: 0.52 | F30: 2026-08-30
A31: 2ch-matome | B31: 2ch修羅場スレ【ゆっくり解説】 | C31: 42000 | D31: 13954 | E31: 0.88 | F31: 2026-08-30
A32: 2ch-matome | B32: ゆっくり2chまとめ解説 | C32: 23800 | D32: 4315 | E32: 1.28 | F32: 2026-08-30
A33: 2ch-matome | B33: ネッカのボケて2chまとめ【ゆっくり解説】 | C33: 20700 | D33: 148822 | E33: 0.8 | F33: 2026-08-30
A34: 2ch-matome | B34: 2ch面白いスレまとめ【ゆっくり解説】 | C34: 13400 | D34: 25517 | E34: 3.33 | F34: 2026-08-30
A35: 2ch-matome | B35: シバ吉のゆっくり2chまとめ | C35: 4780 | D35: 21681 | E35: 2.5 | F35: 2026-08-30
A36: akashic-librarian | B36: 闇世界のツーリスト【ゆっくり解説】 | C36: 797000 | D36: 59287 | E36: 1.69 | F36: 2026-08-30
A37: akashic-librarian | B37: おしえて!オカルト先生 | C37: 366000 | D37: 157753 | E37: 2.37 | F37: 2026-08-30
A38: akashic-librarian | B38: 世界の未解明ミステリー【ゆっくり解説】 | C38: 268000 | D38: 78397 | E38: 0.94 | F38: 2026-08-30
A39: akashic-librarian | B39: オカルトざんまい【ゆっくり解説】 | C39: 196000 | D39: 91601 | E39: 1.66 | F39: 2026-08-30
... A80: yokai-watch | B80: 妖怪解説録 | C80: 16 | D80: 1191 | E80: 4.55 | F80: 2026-08-30
A82: → 競合は週0.5〜2.5本で平均視聴回数が桁違い。本数ではなく1本あたりの質で差がついており、毎日投稿の維持よりCTA・高評価率の改善を優先する根拠になる。
